Workbook

Sheet Data
A1: Requisition_ID | B1: Department | C1: Position | D1: Open_Date | E1: Hire_Date | F1: Time to Fill | G1: Recruitment_Cost | H1: Source | I1: Candidate_Count | J1: Offers_Made | K1: Offers_Accepted | L1: Acceptance Rate | M1: Emp_ID | N1: Training_Hours | O1: Training_Cost | P1: Pre_Test | Q1: Post_Test | R1: Learning Imp | S1: Rating | T1: Attendance_Percent | U1: Performance_Score | V1: Attrition_Status | W1: Gender | X1: Age | Y1: Experience_Years | Z1: Leave_Taken | AA1: Leave_Available | AB1: Salary
A2: REQ001 | B2: Operations | C2: Senior Analyst | D2: 45786 | E2: 45820 | F2: =E2-D2 -> 34 | G2: 33521 | H2: Campus Hiring | I2: 175 | J2: 2 | K2: 1 | L2: =K2/I2 -> 0.0057142857 | M2: E001 | N2: 41 | O2: 17020 | P2: 47 | Q2: 49 | R2: =Q2-P2 -> 2 | S2: 4 | T2: 97 | U2: 79 | V2: Yes | W2: Female | X2: 31 | Y2: 4 | Z2: 6 | AA2: 30 | AB2: 49256
A3: REQ002 | B3: Operations | C3: Senior Analyst | D3: 45558 | E3: 45602 | F3: =E3-D3 -> 44 | G3: 40324 | H3: Walk-In | I3: 151 | J3: 16 | K3: 11 | L3: =K3/I3 -> 0.072847682 | M3: E002 | N3: 9 | O3: 19743 | P3: 74 | Q3: 75 | R3: =Q3-P3 -> 1 | S3: 3 | T3: 97 | U3: 96 | V3: No | W3: Female | X3: 34 | Y3: 11 | Z3: 25 | AA3: 30 | AB3: 41915
A4: REQ003 | B4: HR | C4: Senior Analyst | D4: 45361 | E4: 45409 | F4: =E4-D4 -> 48 | G4: 46735 | H4: Employee Referral | I4: 91 | J4: 1 | K4: 1 | L4: =K4/I4 -> 0.010989011 | M4: E003 | N4: 38 | O4: 27821 | P4: 50 | Q4: 72 | R4: =Q4-P4 -> 22 | S4: 5 | T4: 97 | U4: 75 | V4: Yes | W4: Female | X4: 53 | Y4: 23 | Z4: 17 | AA4: 30 | AB4: 102524
A5: REQ004 | B5: Operations | C5: Senior Analyst | D5: 45613 | E5: 45620 | F5: =E5-D5 -> 7 | G5: 34772 | H5: Naukri | I5: 125 | J5: 18 | K5: 4 | L5: =K5/I5 -> 0.032 | M5: E004 | N5: 17 | O5: 9141 | P5: 70 | Q5: 100 | R5: =Q5-P5 -> 30 | S5: 2 | T5: 83 | U5: 89 | V5: No | W5: Male | X5: 56 | Y5: 24 | Z5: 10 | AA5: 30 | AB5: 116203
A6: REQ005 | B6: HR | C6: Team Lead | D6: 45383 | E6: 45399 | F6: =E6-D6 -> 16 | G6: 22710 | H6: Walk-In | I6: 86 | J6: 15 | K6: 9 | L6: =K6/I6 -> 0.10465116 | M6: E005 | N6: 22 | O6: 1308 | P6: 42 | Q6: 65 | R6: =Q6-P6 -> 23 | S6: 1 | T6: 75 | U6: 67 | V6: No | W6: Male | X6: 37 | Y6: 10 | Z6: 11 | AA6: 30 | AB6: 41275
A7: REQ006 | B7: Operations | C7: Analyst | D7: 45769 | E7: 45805 | F7: =E7-D7 -> 36 | G7: 30292 | H7: Naukri | I7: 79 | J7: 8 | K7: 5 | L7: =K7/I7 -> 0.063291139 | M7: E006 | N7: 9 | O7: 2543 | P7: 44 | Q7: 57 | R7: =Q7-P7 -> 13 | S7: 4 | T7: 96 | U7: 75 | V7: Yes | W7: Male | X7: 25 | Y7: 17 | Z7: 24 | AA7: 30 | AB7: 25027
A8: REQ007 | B8: HR | C8: Associate | D8: 45555 | E8: 45570 | F8: =E8-D8 -> 15 | G8: 31774 | H8: LinkedIn | I8: 157 | J8: 18 | K8: 9 | L8: =K8/I8 -> 0.057324841 | M8: E007 | N8: 57 | O8: 11127 | P8: 45 | Q8: 70 | R8: =Q8-P8 -> 25 | S8: 2 | T8: 91 | U8: 89 | V8: No | W8: Female | X8: 23 | Y8: 17 | Z8: 25 | AA8: 30 | AB8: 110051
A9: REQ008 | B9: Marketing | C9: Senior Analyst | D9: 45695 | E9: 45707 | F9: =E9-D9 -> 12 | G9: 42864 | H9: Walk-In | I9: 52 | J9: 3 | K9: 2 | L9: =K9/I9 -> 0.038461538 | M9: E008 | N9: 49 | O9: 13631 | P9: 81 | Q9: 100 | R9: =Q9-P9 -> 19 | S9: 2 | T9: 80 | U9: 79 | V9: No | W9: Male | X9: 52 | Y9: 15 | Z9: 16 | AA9: 30 | AB9: 55574
A10: REQ009 | B10: HR | C10: Senior Analyst | D10: 45728 | E10: 45764 | F10: =E10-D10 -> 36 | G10: 29448 | H10: Walk-In | I10: 30 | J10: 16 | K10: 9 | L10: =K10/I10 -> 0.3 | M10: E009 | N10: 14 | O10: 3171 | P10: 76 | Q10: 96 | R10: =Q10-P10 -> 20 | S10: 1 | T10: 79 | U10: 69 | V10: No | W10: Female | X10: 52 | Y10: 4 | Z10: 1 | AA10: 30 | AB10: 60942
A11: REQ010 | B11: HR | C11: Manager | D11: 45646 | E11: 45653 | F11: =E11-D11 -> 7 | G11: 19951 | H11: LinkedIn | I11: 107 | J11: 5 | K11: 2 | L11: =K11/I11 -> 0.018691589 | M11: E010 | N11: 72 | O11: 4781 | P11: 45 | Q11: 66 | R11: =Q11-P11 -> 21 | S11: 1 | T11: 89 | U11: 53 | V11: No | W11: Female | X11: 57 | Y11: 1 | Z11: 5 | AA11: 30 | AB11: 51554
A12: REQ011 | B12: HR | C12: Manager | D12: 45588 | E12: 45617 | F12: =E12-D12 -> 29 | G12: 12361 | H12: Naukri | I12: 179 | J12: 19 | K12: 16 | L12: =K12/I12 -> 0.089385475 | M12: E011 | N12: 78 | O12: 6572 | P12: 62 | Q12: 87 | R12: =Q12-P12 -> 25 | S12: 2 | T12: 90 | U12: 98 | V12: No | W12: Female | X12: 32 | Y12: 2 | Z12: 22 | AA12: 30 | AB12: 28609
A13: REQ012 | B13: Operations | C13: Associate | D13: 45691 | E13: 45749 | F13: =E13-D13 -> 58 | G13: 30493 | H13: LinkedIn | I13: 106 | J13: 5 | K13: 2 | L13: =K13/I13 -> 0.018867925 | M13: E012 | N13: 10 | O13: 14629 | P13: 77 | Q13: 93 | R13: =Q13-P13 -> 16 | S13: 5 | T13: 89 | U13: 75 | V13: No | W13: Male | X13: 57 | Y13: 1 | Z13: 12 | AA13: 30 | AB13: 103849
... A201: REQ200 | B201: Operations | C201: Team Lead | D201: 45624 | E201: 45678 | F201: =E201-D201 -> 54 | G201: 24187 | H201: Walk-In | I201: 116 | J201: 10 | K201: 10 | L201: =K201/I201 -> 0.086206897 | M201: E200 | N201: 19 | O201: 21222 | P201: 58 | Q201: 66 | R201: =Q201-P201 -> 8 | S201: 2 | T201: 84 | U201: 61 | V201: No | W201: Female | X201: 30 | Y201: 5 | Z201: 11 | AA201: 30 | AB201: 101475

Sheet Solutions
B1: Exercise 1 – Time to Fill
A2: 1 | B2: Calculate Time to Fill for every position. | C2: Column F
A3: 2 | B3: Find the average Time to Fill. | C3: =AVERAGE(Data!F2:F201) -> 34.365
A4: 3 | B4: Find the maximum Time to Fill. | C4: =MAX(Data!F2:F201) -> 60
A5: 4 | B5: Find the minimum Time to Fill. | C5: =MIN(Data!F2:F201) -> 5
B7: Exercise 2 – Cost per Hire
A8: 5 | B8: Calculate average recruitment cost. | C8: =AVERAGE(Data!G2:G201) -> 27678.88
A9: 6 | B9: Calculate total recruitment cost. | C9: =SUM(Data!G2:G201) -> 5535776
A10: 7 | B10: Identify the most expensive hire. | C10: =MAX(Data!G2:G201) -> 49913
B12: Exercise 3 – Recruitment Source Analysis
A13: 8 | B13: Which source produced the most hires? | C13: {=_xlfn.LET(_xlpm.sources, _xlfn.UNIQUE(Data!H2:H201), _xlpm.hires, SUMIF(Data!H2:H201, _xlpm.sources, Data!K2:K201), _xlfn._xlws.FILTER(_xlpm.sources, _xlpm.hires=MAX(_xlpm.hires)))} -> Naukri
A14: 9 | B14: Which source produced the least hires? | C14: {=_xlfn.LET(_xlpm.sources, _xlfn.UNIQUE(Data!H2:H201), _xlpm.hires, SUMIF(Data!H2:H201, _xlpm.sources, Data!K2:K201), _xlfn._xlws.FILTER(_xlpm.sources, _xlpm.hires=MIN(_xlpm.hires)))} -> Campus Hiring
A15: 10 | B15: Which source has the lowest recruitment cost? | C15: {=_xlfn.LET(_xlpm.sources, _xlfn.UNIQUE(Data!H2:H201), _xlpm.cost, SUMIF(Data!H2:H201,_xlpm.sources, Data!K2:K201), _xlfn._xlws.FILTER(_xlpm.sources,_xlpm.cost=MIN(_xlpm.cost)))} -> Campus Hiring
A16: 11 | B16: Which source has the highest recruitment cost? | C16: {=_xlfn.LET(_xlpm.sources, _xlfn.UNIQUE(Data!H2:H201), _xlpm.cost, SUMIF(Data!H2:H201,_xlpm.sources, Data!K2:K201), _xlfn._xlws.FILTER(_xlpm.sources,_xlpm.cost=MAX(_xlpm.cost)))} -> Naukri
B18: Exercise 4 – Offer Acceptance Rate
A19: 12 | B19: Calculate acceptance rate for each hiring source. | C19: Column L
A20: 13 | B20: Which source has the highest acceptance rate? | C20: =_xlfn.LET(_xlpm.sources,Data!H2:H201,_xlpm.rates,Data!L2:L201,_xlpm.maxrate,MAX(_xlpm.rates),_xlpm.source,INDEX(_xlpm.sources,MATCH(_xlpm.maxrate,_xlpm.rates,0)),_xlpm.source&" - "&TEXT(_xlpm.maxrate,"0.00%")) -> Naukri - 70.00%
B22: Exercise 4 – Training Hours Analysis
A23: 14 | B23: Total Training Hours | C23: =SUM(Data!N2:N201) -> 8009
A24: 15 | B24: Average Training Hours | C24: =AVERAGE(Data!N2:N201) -> 40.045
A25: 16 | B25: Highest Training Hours | C25: =MAX(Data!N2:N201) -> 79
A26: 17 | B26: Lowest Training Hours | C26: =MIN(Data!N2:N201) -> 0
B28: Exercise 5 – Training Cost Analysis
A29: 18 | B29: Total Training Cost | C29: =SUM(Data!O2:O201) -> 3159908
A30: 19 | B30: Average Training Cost | C30: =AVERAGE(Data!O2:O201) -> 15799.54
A31: 20 | B31: Department-wise Training Cost | C31: {=_xlfn.UNIQUE(Data!B2:B201)} -> Operations | D31: {=SUMIF(Data!B2:B201,_xlfn.ANCHORARRAY(Solutions!C31),Data!O2:O201)} -> 499769
C32: HR | D32: 448090
C33: Marketing | D33: 637062
C34: Sales | D34: 471438
C35: Finance | D35: 713052
C36: IT | D36: 390497
B38: Exercise 6 – Learning Improvement %
A39: 21 | B39: Calculate learning improvement. | C39: Column Q
A40: 22 | B40: Identify employees with highest improvement. | C40: {=_xlfn._xlws.FILTER(Data!M2:M201,Data!R2:R201=MAX(Data!R2:R201))} -> E004 | D40: =MAX(Data!$R$2:$R$201) -> 30
C41: E068 | D41: =MAX(Data!$R$2:$R$201) -> 30
C42: E080 | D42: =MAX(Data!$R$2:$R$201) -> 30
A44: 23 | B44: Find average improvement by department. | C44: {=_xlfn.UNIQUE(Data!B2:B201)} -> Operations | D44: {=AVERAGEIF(Data!B2:B201,_xlfn.ANCHORARRAY(Solutions!C44),Data!R2:R201)} -> 12.65625
C45: HR | D45: 16.315789
C46: Marketing | D46: 14.868421
C47: Sales | D47: 15.733333
...
